Workbook

Sheet Inversión Inicial
A1: ESCENARIO BASE DOCUMENTAL: la Fase 1 se planifica en 165.000 € prudente / 180.000 € central / 195.000 € techo. No equivale a caja cobrada.
B2: Inversión Inicial
B4: Inmovilizado Material
B5: Concepto | C5: Adq. a Empresas (sin IVA) | D5: IVA 21% | E5: Adq. a Particulares (ITPYAJD) | F5: ITPYAJD | H5: Aportación en Especie | J5: TOTALES | K5: €
B6: Adquisición del terreno | C6: 0 | D6: =C6*0.21 -> 0 | E6: 0 | F6: 0.08 | G6: =E6*F6 -> 0 | H6: 0 | J6: Inmovilizado Material: | K6: =SUM(C6+C7+C8+C9+C10+C11+C12+C13+C14+C15+C16+E6+E7+E8+E9+E10+E11+E12+E13+E14+E15+E16+H6+H7+H8+H9+H10+H11+H12+H13+H14+H15+H16) -> 10000
B7: Edificios y Construcciones | C7: 0 | D7: =C7*0.21 -> 0 | E7: 0 | F7: 0.08 | G7: =E7*F7 -> 0 | H7: 0 | J7: Inmovilizado Inmaterial: | K7: =C19+C20+C21+C22+C23+C24+C25+E19+E20+E21+E22+E23+E24+E25+H19+H20+H21+H22+H23+H24+H25 -> 82460.72
B8: Instalaciones | C8: 0 | D8: =C8*0.21 -> 0 | E8: 0 | F8: 0.06 | G8: =E8*F8 -> 0 | H8: 0 | J8: Activo no Corriente Total: | K8: =K6+K7 -> 92460.72
B9: Maquinaria | C9: 0 | D9: =C9*0.21 -> 0 | E9: 0 | F9: 0.06 | G9: =E9*F9 -> 0 | H9: 0
B10: Equipamiento | C10: 0 | D10: =C10*0.21 -> 0 | E10: 0 | F10: 0.06 | G10: =E10*F10 -> 0 | H10: 0 | J10: Existencias Iniciales: | K10: =C28+E28+H28 -> 0
B11: Mobiliario | C11: 0 | D11: =C11*0.21 -> 0 | E11: 0 | F11: 0.06 | G11: =E11*F11 -> 0 | H11: 0 | J11: Tesorería inicial para puesta en marcha: | K11: =-('Necesidades de finaciación'!J19) -> 68166.78
B12: Utillaje | C12: 0 | D12: =C12*0.21 -> 0 | E12: 0 | F12: 0.06 | G12: =E12*F12 -> 0 | H12: 0 | J12: IVA Soportad Empresas | K12: =(D6+D7+D8+D9+D10+D11+D12+D13+D14+D15+D16+D19+D20+D21+D22+D23+D24+D25+D28) -> 19372.5
B13: Vehículos de transporte | C13: 0 | D13: =C13*0.21 -> 0 | E13: 0 | F13: 0.06 | G13: =E13*F13 -> 0 | H13: 0 | J13: ITPYAJD Soportado particulares | K13: =G6+G7+G8+G9+G10+G11+G12+G13+G14+G15+G16+G19+G20+G21+G22+G23+G24+G25+G28 -> 0
B14: Equipos informáticos | C14: 0 | D14: =C14*0.21 -> 0 | E14: 0 | F14: 0.06 | G14: =E14*F14 -> 0 | H14: 0 | J14: Activo Corriente Total: | K14: =K12+K13+K10+K11 -> 87539.28
B15: Equipos y medios técnicos F1 (escenario base) | C15: 10000 | D15: =C15*0.21 -> 2100 | E15: 0 | F15: 0.06 | G15: =E15*F15 -> 0 | H15: 0
B16: Fianza | C16: 0 | E16: 0 | F16: 0 | H16: 0 | J16: Necesidades Totales de Aportación en Especie | K16: =K8+K14 -> 180000
B17: Inmovilizado Inmaterial
B18: Concepto | C18: Adq. a Empresas (sin IVA) | D18: IVA 21% | E18: Adq. a Particulares (sin IVA) | F18: IVA | H18: Aportación en Especie
B19: I+D y validación técnica F1 (escenario base) | C19: 30000 | D19: =C19*0.21 -> 6300 | E19: 0 | F19: 0.06 | G19: =E19*F19 -> 0 | H19: 0
B20: Patentes, Modelos de Utilidad | C20: 0 | D20: =C20*0.21 -> 0 | E20: 0 | F20: 0.06 | G20: =E20*F20 -> 0 | H20: 0
B21: Aplicaciones informáticas F1 (escenario base) | C21: 47250 | D21: =C21*0.21 -> 9922.5 | E21: 0 | F21: 0.06 | G21: =E21*F21 -> 0 | H21: 0
B22: Derechos de traspaso, Concesiones administrativas, Tasas, Licencias... | C22: 0 | D22: 0 | E22: 0 | F22: 0 | G22: =E22*F22 -> 0 | H22: 0
B23: Marca, nombre comercial y tasas (documentado/en trámite) | C23: 210.72 | D23: 0 | E23: 0 | F23: 0 | G23: =E23*F23 -> 0 | H23: 0
B24: Legal, administración y contingencia F1 | C24: 5000 | D24: =C24*0.21 -> 1050 | E24: 0 | F24: 0.06 | G24: =E24*0.06 -> 0 | H24: 0
B25: Fondo de Comercio | C25: 0 | D25: 0 | E25: 0 | F25: 0 | G25: =E25*F25 -> 0 | H25: 0
B26: Activo Corriente
B27: Concepto | C27: Adq. a Empresas (sin IVA) | D27: IVA 21% | E27: Adq. a Particulares (sin IVA) | F27: IVA | H27: Aportación en Especie
B28: Existencias Iniciales (M.P., productos terminados, envases y embalajes) | C28: 0 | D28: =C28*0.21 -> 0 | E28: 0 | F28: 0.08 | G28: =E28*0.08 -> 0 | H28: 0

Sheet Pago de Inversiones
B3: Pago de Inversiones
B5: Concepto | C5: Importe Total | D5: % | E5: Mes 0 | F5: % | G5: Mes 1 | H5: % | I5: Mes 2 | J5: % | K5: Mes 3 | L5: % | M5: Mes 4 | N5: % | O5: Mes 5 | P5: % | Q5: Mes 6 | R5: % | S5: Mes 7 | T5: % | U5: Mes 8 | V5: % | W5: Mes 9 | X5: % | Y5: Mes 10 | Z5: % | AA5: Mes 11 | AB5: % | AC5: Mes 12 | AD5: Calculo correcto
B6: Adquisición del terreno | C6: ='Inversión Inicial'!C6+'Inversión Inicial'!D6+'Inversión Inicial'!E6+'Inversión Inicial'!G6 -> 0 | D6: 0 | E6: =(C6*D6) -> 0 | F6: 0 | G6: =C6*F6 -> 0 | H6: 0 | I6: =C6*H6 -> 0 | J6: 0 | K6: =C6*J6 -> 0 | L6: 0 | M6: =C6*L6 -> 0 | N6: 0 | O6: =C6*N6 -> 0 | P6: 0 | Q6: =C6*P6 -> 0 | R6: 0 | S6: =C6*R6 -> 0 | T6: 0 | U6: =C6*T6 -> 0 | V6: 0 | W6: =C6*V6 -> 0 | X6: 0 | Y6: =C6*X6 -> 0 | Z6: 0 | AA6: =C6*Z6 -> 0 | AB6: 0 | AC6: =C6*AB6 -> 0 | AD6: =E6+G6+I6+K6+M6+O6+Q6+S6+U6+W6+Y6+AA6+AC6-C6 -> 0
B7: Edificios y Construcciones | C7: ='Inversión Inicial'!C7+'Inversión Inicial'!D7+'Inversión Inicial'!E7+'Inversión Inicial'!G7 -> 0 | D7: 0 | E7: =(C7*D7) -> 0 | F7: 0 | G7: =C7*F7 -> 0 | H7: 0 | I7: =C7*H7 -> 0 | J7: 0 | K7: =C7*J7 -> 0 | L7: 0 | M7: =C7*L7 -> 0 | N7: 0 | O7: =C7*N7 -> 0 | P7: 0 | Q7: =C7*P7 -> 0 | R7: 0 | S7: =C7*R7 -> 0 | T7: 0 | U7: =C7*T7 -> 0 | V7: 0 | W7: =C7*V7 -> 0 | X7: 0 | Y7: =C7*X7 -> 0 | Z7: 0 | AA7: =C7*Z7 -> 0 | AB7: 0 | AC7: =C7*AB7 -> 0 | AD7: =E7+G7+I7+K7+M7+O7+Q7+S7+U7+W7+Y7+AA7+AC7-C7 -> 0
B8: Instalaciones | C8: ='Inversión Inicial'!C8+'Inversión Inicial'!D8+'Inversión Inicial'!E8+'Inversión Inicial'!G8 -> 0 | D8: 0 | E8: =(C8*D8) -> 0 | F8: 0 | G8: =C8*F8 -> 0 | H8: 0 | I8: =C8*H8 -> 0 | J8: 0 | K8: =C8*J8 -> 0 | L8: 0 | M8: =C8*L8 -> 0 | N8: 0 | O8: =C8*N8 -> 0 | P8: 0 | Q8: =C8*P8 -> 0 | R8: 0 | S8: =C8*R8 -> 0 | T8: 0 | U8: =C8*T8 -> 0 | V8: 0 | W8: =C8*V8 -> 0 | X8: 0 | Y8: =C8*X8 -> 0 | Z8: 0 | AA8: =C8*Z8 -> 0 | AB8: 0 | AC8: =C8*AB8 -> 0 | AD8: =E8+G8+I8+K8+M8+O8+Q8+S8+U8+W8+Y8+AA8+AC8-C8 -> 0
B9: Maquinaria | C9: ='Inversión Inicial'!C9+'Inversión Inicial'!D9+'Inversión Inicial'!E9+'Inversión Inicial'!G9 -> 0 | D9: 0 | E9: =(C9*D9) -> 0 | F9: 0 | G9: =C9*F9 -> 0 | H9: 0 | I9: =C9*H9 -> 0 | J9: 0 | K9: =C9*J9 -> 0 | L9: 0 | M9: =C9*L9 -> 0 | N9: 0 | O9: =C9*N9 -> 0 | P9: 0 | Q9: =C9*P9 -> 0 | R9: 0 | S9: =C9*R9 -> 0 | T9: 0 | U9: =C9*T9 -> 0 | V9: 0 | W9: =C9*V9 -> 0 | X9: 0 | Y9: =C9*X9 -> 0 | Z9: 0 | AA9: =C9*Z9 -> 0 | AB9: 0 | AC9: =C9*AB9 -> 0 | AD9: =E9+G9+I9+K9+M9+O9+Q9+S9+U9+W9+Y9+AA9+AC9-C9 -> 0
B10: Equipamiento | C10: ='Inversión Inicial'!C10+'Inversión Inicial'!D10+'Inversión Inicial'!E10+'Inversión Inicial'!G10 -> 0 | D10: 0 | E10: =(C10*D10) -> 0 | F10: 0 | G10: =C10*F10 -> 0 | H10: 0 | I10: =C10*H10 -> 0 | J10: 0 | K10: =C10*J10 -> 0 | L10: 0 | M10: =C10*L10 -> 0 | N10: 0 | O10: =C10*N10 -> 0 | P10: 0 | Q10: =C10*P10 -> 0 | R10: 0 | S10: =C10*R10 -> 0 | T10: 0 | U10: =C10*T10 -> 0 | V10: 0 | W10: =C10*V10 -> 0 | X10: 0 | Y10: =C10*X10 -> 0 | Z10: 0 | AA10: =C10*Z10 -> 0 | AB10: 0 | AC10: =C10*AB10 -> 0 | AD10: =E10+G10+I10+K10+M10+O10+Q10+S10+U10+W10+Y10+AA10+AC10-C10 -> 0
B11: Mobiliario | C11: ='Inversión Inicial'!C11+'Inversión Inicial'!D11+'Inversión Inicial'!E11+'Inversión Inicial'!G11 -> 0 | D11: 0 | E11: =(C11*D11) -> 0 | F11: 0 | G11: =C11*F11 -> 0 | H11: 0 | I11: =C11*H11 -> 0 | J11: 0 | K11: =C11*J11 -> 0 | L11: 0 | M11: =C11*L11 -> 0 | N11: 0 | O11: =C11*N11 -> 0 | P11: 0 | Q11: =C11*P11 -> 0 | R11: 0 | S11: =C11*R11 -> 0 | T11: 0 | U11: =C11*T11 -> 0 | V11: 0 | W11: =C11*V11 -> 0 | X11: 0 | Y11: =C11*X11 -> 0 | Z11: 0 | AA11: =C11*Z11 -> 0 | AB11: 0 | AC11: =C11*AB11 -> 0 | AD11: =E11+G11+I11+K11+M11+O11+Q11+S11+U11+W11+Y11+AA11+AC11-C11 -> 0
B12: Utillaje | C12: ='Inversión Inicial'!C12+'Inversión Inicial'!D12+'Inversión Inicial'!E12+'Inversión Inicial'!G12 -> 0 | D12: 0 | E12: =(C12*D12) -> 0 | F12: 0 | G12: =C12*F12 -> 0 | H12: 0 | I12: =C12*H12 -> 0 | J12: 0 | K12: =C12*J12 -> 0 | L12: 0 | M12: =C12*L12 -> 0 | N12: 0 | O12: =C12*N12 -> 0 | P12: 0 | Q12: =C12*P12 -> 0 | R12: 0 | S12: =C12*R12 -> 0 | T12: 0 | U12: =C12*T12 -> 0 | V12: 0 | W12: =C12*V12 -> 0 | X12: 0 | Y12: =C12*X12 -> 0 | Z12: 0 | AA12: =C12*Z12 -> 0 | AB12: 0 | AC12: =C12*AB12 -> 0 | AD12: =E12+G12+I12+K12+M12+O12+Q12+S12+U12+W12+Y12+AA12+AC12-C12 -> 0
B13: Vehículos de transporte | C13: ='Inversión Inicial'!C13+'Inversión Inicial'!D13+'Inversión Inicial'!E13+'Inversión Inicial'!G13 -> 0 | D13: 0 | E13: =(C13*D13) -> 0 | F13: 0 | G13: =C13*F13 -> 0 | H13: 0 | I13: =C13*H13 -> 0 | J13: 0 | K13: =C13*J13 -> 0 | L13: 0 | M13: =C13*L13 -> 0 | N13: 0 | O13: =C13*N13 -> 0 | P13: 0 | Q13: =C13*P13 -> 0 | R13: 0 | S13: =C13*R13 -> 0 | T13: 0 | U13: =C13*T13 -> 0 | V13: 0 | W13: =C13*V13 -> 0 | X13: 0 | Y13: =C13*X13 -> 0 | Z13: 0 | AA13: =C13*Z13 -> 0 | AB13: 0 | AC13: =C13*AB13 -> 0 | AD13: =E13+G13+I13+K13+M13+O13+Q13+S13+U13+W13+Y13+AA13+AC13-C13 -> 0
B14: Equipos informáticos | C14: ='Inversión Inicial'!C14+'Inversión Inicial'!D14+'Inversión Inicial'!E14+'Inversión Inicial'!G14 -> 0 | D14: 0 | E14: =(C14*D14) -> 0 | F14: 0 | G14: =C14*F14 -> 0 | H14: 0 | I14: =C14*H14 -> 0 | J14: 0 | K14: =C14*J14 -> 0 | L14: 0 | M14: =C14*L14 -> 0 | N14: 0 | O14: =C14*N14 -> 0 | P14: 0 | Q14: =C14*P14 -> 0 | R14: 0 | S14: =C14*R14 -> 0 | T14: 0 | U14: =C14*T14 -> 0 | V14: 0 | W14: =C14*V14 -> 0 | X14: 0 | Y14: =C14*X14 -> 0 | Z14: 0 | AA14: =C14*Z14 -> 0 | AB14: 0 | AC14: =C14*AB14 -> 0 | AD14: =E14+G14+I14+K14+M14+O14+Q14+S14+U14+W14+Y14+AA14+AC14-C14 -> 0
B15: Otros (proyectos técnicos...) | C15: ='Inversión Inicial'!C15+'Inversión Inicial'!D15+'Inversión Inicial'!E15+'Inversión Inicial'!G15 -> 12100 | D15: 0 | E15: =(C15*D15) -> 0 | F15: 0 | G15: =C15*F15 -> 0 | H15: 0 | I15: =C15*H15 -> 0 | J15: 0 | K15: =C15*J15 -> 0 | L15: 0 | M15: =C15*L15 -> 0 | N15: 0 | O15: =C15*N15 -> 0 | P15: 0 | Q15: =C15*P15 -> 0 | R15: 0 | S15: =C15*R15 -> 0 | T15: 0 | U15: =C15*T15 -> 0 | V15: 0 | W15: =C15*V15 -> 0 | X15: 0 | Y15: =C15*X15 -> 0 | Z15: 0 | AA15: =C15*Z15 -> 0 | AB15: 0 | AC15: =C15*AB15 -> 0 | AD15: =E15+G15+I15+K15+M15+O15+Q15+S15+U15+W15+Y15+AA15+AC15-C15 -> -12100
B16: Gastos de I+D | C16: ='Inversión Inicial'!C19+'Inversión Inicial'!D19+'Inversión Inicial'!E19+'Inversión Inicial'!G19 -> 36300 | D16: 0 | E16: =(C16*D16) -> 0 | F16: 0 | G16: =C16*F16 -> 0 | H16: 0 | I16: =C16*H16 -> 0 | J16: 0 | K16: =C16*J16 -> 0 | L16: 0 | M16: =C16*L16 -> 0 | N16: 0 | O16: =C16*N16 -> 0 | P16: 0 | Q16: =C16*P16 -> 0 | R16: 0 | S16: =C16*R16 -> 0 | T16: 0 | U16: =C16*T16 -> 0 | V16: 0 | W16: =C16*V16 -> 0 | X16: 0 | Y16: =C16*X16 -> 0 | Z16: 0 | AA16: =C16*Z16 -> 0 | AB16: 0 | AC16: =C16*AB16 -> 0 | AD16: =E16+G16+I16+K16+M16+O16+Q16+S16+U16+W16+Y16+AA16+AC16-C16 -> -36300
B17: Patentes, Modelos de Utilidad | C17: ='Inversión Inicial'!C20+'Inversión Inicial'!D20+'Inversión Inicial'!E20+'Inversión Inicial'!G20 -> 0 | D17: 0 | E17: =(C17*D17) -> 0 | F17: 0 | G17: =C17*F17 -> 0 | H17: 0 | I17: =C17*H17 -> 0 | J17: 0 | K17: =C17*J17 -> 0 | L17: 0 | M17: =C17*L17 -> 0 | N17: 0 | O17: =C17*N17 -> 0 | P17: 0 | Q17: =C17*P17 -> 0 | R17: 0 | S17: =C17*R17 -> 0 | T17: 0 | U17: =C17*T17 -> 0 | V17: 0 | W17: =C17*V17 -> 0 | X17: 0 | Y17: =C17*X17 -> 0 | Z17: 0 | AA17: =C17*Z17 -> 0 | AB17: 0 | AC17: =C17*AB17 -> 0 | AD17: =E17+G17+I17+K17+M17+O17+Q17+S17+U17+W17+Y17+AA17+AC17-C17 -> 0
B18: Aplicaciones informáticas | C18: ='Inversión Inicial'!C21+'Inversión Inicial'!D21+'Inversión Inicial'!E21+'Inversión Inicial'!G21 -> 57172.5 | D18: 0 | E18: =(C18*D18) -> 0 | F18: 0 | G18: =C18*F18 -> 0 | H18: 0 | I18: =C18*H18 -> 0 | J18: 0 | K18: =C18*J18 -> 0 | L18: 0 | M18: =C18*L18 -> 0 | N18: 0 | O18: =C18*N18 -> 0 | P18: 0 | Q18: =C18*P18 -> 0 | R18: 0 | S18: =C18*R18 -> 0 | T18: 0 | U18: =C18*T18 -> 0 | V18: 0 | W18: =C18*V18 -> 0 | X18: 0 | Y18: =C18*X18 -> 0 | Z18: 0 | AA18: =C18*Z18 -> 0 | AB18: 0 | AC18: =C18*AB18 -> 0 | AD18: =E18+G18+I18+K18+M18+O18+Q18+S18+U18+W18+Y18+AA18+AC18-C18 -> -57172.5
B19: Derechos de traspaso, Concesiones administrativas, Tasas, Licencias... | C19: ='Inversión Inicial'!C22+'Inversión Inicial'!E22+'Inversión Inicial'!G22 -> 0 | D19: 0 | E19: =(C19*D19) -> 0 | F19: 0 | G19: =C19*F19 -> 0 | H19: 0 | I19: =C19*H19 -> 0 | J19: 0 | K19: =C19*J19 -> 0 | L19: 0 | M19: =C19*L19 -> 0 | N19: 0 | O19: =C19*N19 -> 0 | P19: 0 | Q19: =C19*P19 -> 0 | R19: 0 | S19: =C19*R19 -> 0 | T19: 0 | U19: =C19*T19 -> 0 | V19: 0 | W19: =C19*V19 -> 0 | X19: 0 | Y19: =C19*X19 -> 0 | Z19: 0 | AA19: =C19*Z19 -> 0 | AB19: 0 | AC19: =C19*AB19 -> 0 | AD19: =E19+G19+I19+K19+M19+O19+Q19+S19+U19+W19+Y19+AA19+AC19-C19 -> 0
B20: Marca, Nombre Comercial | C20: ='Inversión Inicial'!C23+'Inversión Inicial'!E23+'Inversión Inicial'!G23 -> 210.72 | D20: 0 | E20: =(C20*D20) -> 0 | F20: 0 | G20: =C20*F20 -> 0 | H20: 0 | I20: =C20*H20 -> 0 | J20: 0 | K20: =C20*J20 -> 0 | L20: 0 | M20: =C20*L20 -> 0 | N20: 0 | O20: =C20*N20 -> 0 | P20: 0 | Q20: =C20*P20 -> 0 | R20: 0 | S20: =C20*R20 -> 0 | T20: 0 | U20: =C20*T20 -> 0 | V20: 0 | W20: =C20*V20 -> 0 | X20: 0 | Y20: =C20*X20 -> 0 | Z20: 0 | AA20: =C20*Z20 -> 0 | AB20: 0 | AC20: =C20*AB20 -> 0 | AD20: =E20+G20+I20+K20+M20+O20+Q20+S20+U20+W20+Y20+AA20+AC20-C20 -> -210.72
B21: Otros (...) | C21: ='Inversión Inicial'!C24+'Inversión Inicial'!D24+'Inversión Inicial'!E24+'Inversión Inicial'!G24 -> 6050 | D21: 0 | E21: =(C21*D21) -> 0 | F21: 0 | G21: =C21*F21 -> 0 | H21: 0 | I21: =C21*H21 -> 0 | J21: 0 | K21: =C21*J21 -> 0 | L21: 0 | M21: =C21*L21 -> 0 | N21: 0 | O21: =C21*N21 -> 0 | P21: 0 | Q21: =C21*P21 -> 0 | R21: 0 | S21: =C21*R21 -> 0 | T21: 0 | U21: =C21*T21 -> 0 | V21: 0 | W21: =C21*V21 -> 0 | X21: 0 | Y21: =C21*X21 -> 0 | Z21: 0 | AA21: =C21*Z21 -> 0 | AB21: 0 | AC21: =C21*AB21 -> 0 | AD21: =E21+G21+I21+K21+M21+O21+Q21+S21+U21+W21+Y21+AA21+AC21-C21 -> -6050
B22: Fondo de Comercio | C22: ='Inversión Inicial'!C25+'Inversión Inicial'!E25 -> 0 | D22: 0 | E22: =(C22*D22) -> 0 | F22: 0 | G22: =C22*F22 -> 0 | H22: 0 | I22: =C22*H22 -> 0 | J22: 0 | K22: =C22*J22 -> 0 | L22: 0 | M22: =C22*L22 -> 0 | N22: 0 | O22: =C22*N22 -> 0 | P22: 0 | Q22: =C22*P22 -> 0 | R22: 0 | S22: =C22*R22 -> 0 | T22: 0 | U22: =C22*T22 -> 0 | V22: 0 | W22: =C22*V22 -> 0 | X22: 0 | Y22: =C22*X22 -> 0 | Z22: 0 | AA22: =C22*Z22 -> 0 | AB22: 0 | AC22: =C22*AB22 -> 0 | AD22: =E22+G22+I22+K22+M22+O22+Q22+S22+U22+W22+Y22+AA22+AC22-C22 -> 0
B23: Existencias Iniciales (M.P., productos terminados, envases y embalajes) | C23: ='Inversión Inicial'!C28+'Inversión Inicial'!D28+'Inversión Inicial'!E28+'Inversión Inicial'!G28 -> 0 | D23: 0 | E23: =(C23*D23) -> 0 | F23: 0 | G23: =C23*F23 -> 0 | H23: 0 | I23: =C23*H23 -> 0 | J23: 0 | K23: =C23*J23 -> 0 | L23: 0 | M23: =C23*L23 -> 0 | N23: 0 | O23: =C23*N23 -> 0 | P23: 0 | Q23: =C23*P23 -> 0 | R23: 0 | S23: =C23*R23 -> 0 | T23: 0 | U23: =C23*T23 -> 0 | V23: 0 | W23: =C23*V23 -> 0 | X23: 0 | Y23: =C23*X23 -> 0 | Z23: 0 | AA23: =C23*Z23 -> 0 | AB23: 0 | AC23: =C23*AB23 -> 0 | AD23: =E23+G23+I23+K23+M23+O23+Q23+S23+U23+W23+Y23+AA23+AC23-C23 -> 0
B24: Fianza | C24: ='Inversión Inicial'!C16+'Inversión Inicial'!D16+'Inversión Inicial'!E16+'Inversión Inicial'!G16 -> 0 | D24: 0 | E24: =(C24*D24) -> 0 | F24: 0 | G24: =C24*F24 -> 0 | H24: 0 | I24: =C24*H24 -> 0 | J24: 0 | K24: =C24*J24 -> 0 | L24: 0 | M24: =C24*L24 -> 0 | N24: 0 | O24: =C24*N24 -> 0 | P24: 0 | Q24: =C24*P24 -> 0 | R24: 0 | S24: =C24*R24 -> 0 | T24: 0 | U24: =C24*T24 -> 0 | V24: 0 | W24: =C24*V24 -> 0 | X24: 0 | Y24: =C24*X24 -> 0 | Z24: 0 | AA24: =C24*Z24 -> 0 | AB24: 0 | AC24: =C24*AB24 -> 0 | AD24: =E24+G24+I24+K24+M24+O24+Q24+S24+U24+W24+Y24+AA24+AC24-C24 -> 0
B25: TOTALES | C25: =SUM(C6:C24) -> 111833.22 | E25: =SUM(E6:E24) -> 0 | G25: =SUM(G6:G24) -> 0 | I25: =SUM(I6:I24) -> 0 | K25: =SUM(K6:K24) -> 0 | M25: =SUM(M6:M24) -> 0 | O25: =SUM(O6:O24) -> 0 | Q25: =SUM(Q6:Q24) -> 0 | S25: =SUM(S6:S24) -> 0 | U25: =SUM(U6:U24) -> 0 | W25: =SUM(W6:W24) -> 0 | Y25: =SUM(Y6:Y24) -> 0 | AA25: =SUM(AA6:AA24) -> 0 | AC25: =SUM(AC6:AC24) -> 0 | AD25: =E25+G25+I25+K25+M25+O25+Q25+S25+U25+W25+Y25+AA25+AC25-C25 -> -111833.22
B27: Sólo tienes que completar el % que vas a imputar a cada mes, el resto se calcula de manera automática.

Sheet Necesidades de finaciación
A1: ESCENARIO PROFORMA — NO ES FINANCIACIÓN CONCEDIDA NI COBRADA
A2: La financiación cobrada y la caja propia inicial son ambas 0,00 €. El Excel reproduce únicamente un escenario condicionado a formalización y desembolso.
B3: Necesidades de Financiación
B6: Recursos Propios
I7: TOTALES | J7: €
B8: Concepto | F8: Importe | I8: Aportaciones en especies | J8: ='Inversión Inicial'!H6+'Inversión Inicial'!H7+'Inversión Inicial'!H8+'Inversión Inicial'!H9+'Inversión Inicial'!H10+'Inversión Inicial'!H11+'Inversión Inicial'!H12+'Inversión Inicial'!H13+'Inversión Inicial'!H14+'Inversión Inicial'!H15+'Inversión Inicial'!H16+'Inversión Inicial'!H19+'Inversión Inicial'!H20+'Inversión Inicial'!H21+'Inversión Inicial'!H22+'Inversión Inicial'!H23+'Inversión Inicial'!H24+'Inversión Inicial'!H25+'Inversión Inicial'!H28 -> 0
B9: Aportaciones Dinerarias | F9: 0 | I9: Aportaciones de socios total: | J9: =F9+J8 -> 0
B10: Otros (pago único desempleado, subvenciones cobradas, …) | F10: 0 | I10: Recursos propios: | J10: =F9+F10+J8 -> 0
I12: Deudas Bancarias | J12: =F17+F18 -> 180000
B13: Recursos Ajenos a Largo Plazo | I13: Recursos Ajenos a L/P | J13: =F16+J12 -> 180000
B15: Concepto | F15: Importe | G15: Años | H15: Tipo de interés nominal anual | I15: Proveedores Varios C/P | J15: ='Pago de Inversiones'!G25+'Pago de Inversiones'!I25+'Pago de Inversiones'!K25+'Pago de Inversiones'!M25+'Pago de Inversiones'!O25+'Pago de Inversiones'!Q25+'Pago de Inversiones'!S25+'Pago de Inversiones'!U25+'Pago de Inversiones'!W25+'Pago de Inversiones'!Y25+'Pago de Inversiones'!AA25+'Pago de Inversiones'!AC25+F24 -> 0
B16: Otras deudas a largo plazo | F16: 0
B17: Financiación externa central F1 — pendiente de formalización y desembolso | F17: 180000 | G17: 7 | H17: 0.07 | I17: Pasivo Total | J17: =J10+J15+J13 -> 180000
B18: Microcrédito | F18: 0 | G18: 0 | H18: 0
I19: ='Inversión Inicial'!J16 -> Necesidades Totales de Aportación en Especie | J19: =('Inversión Inicial'!K8+'Inversión Inicial'!K10+'Inversión Inicial'!K12+'Inversión Inicial'!K13)-J17 -> -68166.78
B21: Recursos Ajenos a Corto Plazo
B23: Concepto | F23: Importe | H23: Tipo de interés nominal anual
B24: Deudas a Corto Plazo | F24: 0 | H24: 0
A25: Liquidez: caja propia inicial 0 €. La financiación externa central de 180.000 € requiere póliza/préstamo de emprendimiento o desembolso documentado. El flujo oficial solo la simula en escenario proforma condicionado.

Sheet Costes produción y ventas
B2: COSTES DE PRODUCIÓN
B3: Producto | C3: Precio/unid | D3: % IVA | E3: Sub/Total/unid | F3: Total unidades año | G3: Total € anual (IVA incl)
A4: soportado | B4: SaaS agro-energético y cuaderno digital | C4: 65 | D4: 0.21 | E4: =C4*D4+C4 -> 78.65 | F4: 72 | G4: =E4*F4 -> 5662.8
B5: Implantación y parametrización | C5: 300 | D5: 0.21 | E5: =C5*D5+C5 -> 363 | F5: 5 | G5: =E5*F5 -> 1815
B6: Formación y acompañamiento | C6: 150 | D6: 0.21 | E6: =C6*D6+C6 -> 181.5 | F6: 9 | G6: =E6*F6 -> 1633.5
B7: Kit sensórico e integración de campo | C7: 400 | D7: 0.21 | E7: =C7*D7+C7 -> 484 | F7: 5 | G7: =E7*F7 -> 2420
B8: Consultoría y evidencias | C8: 391.5 | D8: 0.21 | E8: =C8*D8+C8 -> 473.715 | F8: 3 | G8: =E8*F8 -> 1421.145
B11: INGRESOS POR VENTA
B12: Producto | C12: Precio/unid | D12: % IVA | E12: Sub/Total/unid | F12: Total unidades año | G12: Total € anual (IVA incl)
A13: repercutido | B13: =B4 -> SaaS agro-energético y cuaderno digital | C13: 250 | D13: 0.21 | E13: =C13*D13+C13 -> 302.5 | F13: =F4 -> 72 | G13: =E13*F13 -> 21780
B14: =B5 -> Implantación y parametrización | C14: 1500 | D14: 0.21 | E14: =C14*D14+C14 -> 1815 | F14: =F5 -> 5 | G14: =E14*F14 -> 9075
B15: =B6 -> Formación y acompañamiento | C15: 500 | D15: 0.21 | E15: =C15*D15+C15 -> 605 | F15: =F6 -> 9 | G15: =E15*F15 -> 5445
B16: =B7 -> Kit sensórico e integración de campo | C16: 1200 | D16: 0.21 | E16: =C16*D16+C16 -> 1452 | F16: =F7 -> 5 | G16: =E16*F16 -> 7260
B17: =B8 -> Consultoría y evidencias | C17: 1166.6667 | D17: 0.21 | E17: =C17*D17+C17 -> 1411.6667 | F17: =F8 -> 3 | G17: =E17*F17 -> 4235
G19: INGRESOS POR VENTAS ANUALES
D20: =B4 -> SaaS agro-energético y cuaderno digital | G20: TOTAL | H20: Mes 1 | I20: Mes 2 | J20: Mes 3 | K20: Mes 4 | L20: Mes 5 | M20: Mes 6 | N20: Mes 7 | O20: Mes 8 | P20: Mes 9 | Q20: Mes 10 | R20: Mes 11 | S20: Mes 12 | T20: Salir exacto
D21: Nº Productos/Servicios | G21: =F4 -> 72 | H21: 0 | I21: 0 | J21: 2 | K21: 3 | L21: 4 | M21: 5 | N21: 6 | O21: 7 | P21: 8 | Q21: 9 | R21: 13 | S21: 15 | T21: =G21-H21-I21-J21-K21-L21-M21-N21-O21-P21-Q21-R21-S21 -> 0
D22: Precio de venta | G22: =C13 -> 250 | H22: =G22 -> 250 | I22: =G22 -> 250 | J22: =G22 -> 250 | K22: =G22 -> 250 | L22: =G22 -> 250 | M22: =G22 -> 250 | N22: =G22 -> 250 | O22: =G22 -> 250 | P22: =G22 -> 250 | Q22: =G22 -> 250 | R22: =G22 -> 250 | S22: =G22 -> 250
D23: Ingresos ventas | G23: =G21*G22 -> 18000 | H23: =H21*H22 -> 0 | I23: =I21*I22 -> 0 | J23: =J21*J22 -> 500 | K23: =K21*K22 -> 750 | L23: =L21*L22 -> 1000 | M23: =M21*M22 -> 1250 | N23: =N21*N22 -> 1500 | ... S23: =S21*S22 -> 3750 | T23: =G23-H23-I23-J23-K23-L23-M23-N23-O23-P23-Q23-R23-S23 -> 0
D24: Costes producción | G24: =C4*F4 -> 4680 | H24: =H21*C4 -> 0 | I24: =I21*C4 -> 0 | J24: =J21*C4 -> 130 | K24: =K21*C4 -> 195 | L24: =L21*C4 -> 260 | M24: =M21*C4 -> 325 | N24: =N21*C4 -> 390 | O24: =O21*C4 -> 455 | P24: =P21*C4 -> 520 | Q24: =Q21*C4 -> 585 | R24: =R21*C4 -> 845 | S24: =S21*C4 -> 975 | T24: =G24-H24-I24-J24-K24-L24-M24-N24-O24-P24-Q24-R24-S24 -> 0
D25: Margen Bruto | G25: =G23-G24 -> 13320 | H25: =H23-H24 -> 0 | I25: =I23-I24 -> 0 | J25: =J23-J24 -> 370 | K25: =K23-K24 -> 555 | L25: =L23-L24 -> 740 | M25: =M23-M24 -> 925 | N25: =N23-N24 -> 1110 | ... S25: =S23-S24 -> 2775 | T25: =G25-H25-I25-J25-K25-L25-M25-N25-O25-P25-Q25-R25-S25 -> 0
G27: INGRESOS POR VENTAS ANUALES
D28: =B5 -> Implantación y parametrización | G28: TOTAL | H28: Mes 1 | I28: Mes 2 | J28: Mes 3 | K28: Mes 4 | L28: Mes 5 | M28: Mes 6 | N28: Mes 7 | O28: Mes 8 | P28: Mes 9 | Q28: Mes 10 | R28: Mes 11 | S28: Mes 12 | T28: Salir exacto
D29: Nº Productos/Servicios | G29: =F5 -> 5 | H29: 0 | I29: 0 | J29: 0 | K29: 0 | L29: 0 | M29: 1 | N29: 1 | O29: 1 | P29: 1 | Q29: 1 | R29: 0 | S29: 0 | T29: =G29-H29-I29-J29-K29-L29-M29-N29-O29-P29-Q29-R29-S29 -> 0
D30: Precio de venta | G30: =C14 -> 1500 | H30: =G30 -> 1500 | I30: =G30 -> 1500 | J30: =G30 -> 1500 | K30: =G30 -> 1500 | L30: =G30 -> 1500 | M30: =G30 -> 1500 | N30: =G30 -> 1500 | O30: =G30 -> 1500 | P30: =G30 -> 1500 | Q30: =G30 -> 1500 | R30: =G30 -> 1500 | S30: =G30 -> 1500
D31: Ingresos ventas | G31: =G29*G30 -> 7500 | H31: =H29*H30 -> 0 | I31: =I29*I30 -> 0 | J31: =J29*J30 -> 0 | K31: =K29*K30 -> 0 | L31: =L29*L30 -> 0 | M31: =M29*M30 -> 1500 | N31: =N29*N30 -> 1500 | ... S31: =S29*S30 -> 0 | T31: =G31-H31-I31-J31-K31-L31-M31-N31-O31-P31-Q31-R31-S31 -> 0
D32: Costes producción | G32: =F5*C5 -> 1500 | H32: =H29*C5 -> 0 | I32: =I29*C5 -> 0 | J32: =C5*J29 -> 0 | K32: =K29*C5 -> 0 | L32: =L29*C5 -> 0 | M32: =M29*C5 -> 300 | N32: =N29*C5 -> 300 | O32: =O29*C5 -> 300 | P32: =P29*C5 -> 300 | Q32: =Q29*C5 -> 300 | R32: =R29*C5 -> 0 | S32: =S29*C5 -> 0 | T32: =G32-H32-I32-J32-K32-L32-M32-N32-O32-P32-Q32-R32-S32 -> 0
D33: Margen Bruto | G33: =G31-G32 -> 6000 | H33: =H31-H32 -> 0 | I33: =I31-I32 -> 0 | J33: =J31-J32 -> 0 | K33: =K31-K32 -> 0 | L33: =L31-L32 -> 0 | M33: =M31-M32 -> 1200 | N33: =N31-N32 -> 1200 | ... S33: =S31-S32 -> 0 | T33: =G33-H33-I33-J33-K33-L33-M33-N33-O33-P33-Q33-R33-S33 -> 0
G35: INGRESOS POR VENTAS ANUALES
D36: =B6 -> Formación y acompañamiento | G36: TOTAL | H36: Mes 1 | I36: Mes 2 | J36: Mes 3 | K36: Mes 4 | L36: Mes 5 | M36: Mes 6 | N36: Mes 7 | O36: Mes 8 | P36: Mes 9 | Q36: Mes 10 | R36: Mes 11 | S36: Mes 12 | T36: Salir exacto
D37: Nº Productos/Servicios | G37: =F6 -> 9 | H37: 0 | I37: 0 | J37: 0 | K37: 1 | L37: 1 | M37: 1 | N37: 1 | O37: 1 | P37: 1 | Q37: 1 | R37: 1 | S37: 1 | T37: =G37-H37-I37-J37-K37-L37-M37-N37-O37-P37-Q37-R37-S37 -> 0
D38: Precio de venta | G38: =C15 -> 500 | H38: =G38 -> 500 | I38: =G38 -> 500 | J38: =G38 -> 500 | K38: =G38 -> 500 | L38: =G38 -> 500 | M38: =G38 -> 500 | N38: =G38 -> 500 | O38: =G38 -> 500 | P38: =G38 -> 500 | Q38: =G38 -> 500 | R38: =G38 -> 500 | S38: =G38 -> 500
D39: Ingresos ventas | G39: =G37*G38 -> 4500 | H39: =H37*H38 -> 0 | I39: =I37*I38 -> 0 | J39: =J37*J38 -> 0 | K39: =K37*K38 -> 500 | L39: =L37*L38 -> 500 | M39: =M37*M38 -> 500 | N39: =N37*N38 -> 500 | ... S39: =S37*S38 -> 500 | T39: =G39-H39-I39-J39-K39-L39-M39-N39-O39-P39-Q39-R39-S39 -> 0
D40: Costes producción | G40: =C6*F6 -> 1350 | H40: =H37*C6 -> 0 | I40: =I37*C6 -> 0 | J40: =J37*C6 -> 0 | K40: =K37*C6 -> 150 | L40: =L37*C6 -> 150 | M40: =M37*C6 -> 150 | N40: =N37*C6 -> 150 | O40: =O37*C6 -> 150 | P40: =P37*C6 -> 150 | Q40: =Q37*C6 -> 150 | R40: =R37*C6 -> 150 | S40: =S37*C6 -> 150 | T40: =G40-H40-I40-J40-K40-L40-M40-N40-O40-P40-Q40-R40-S40 -> 0
D41: Margen Bruto | G41: =G39-G40 -> 3150 | H41: =H39-H40 -> 0 | I41: =I39-I40 -> 0 | J41: =J39-J40 -> 0 | K41: =K39-K40 -> 350 | L41: =L39-L40 -> 350 | M41: =M39-M40 -> 350 | N41: =N39-N40 -> 350 | ... S41: =S39-S40 -> 350 | T41: =G41-H41-I41-J41-K41-L41-M41-N41-O41-P41-Q41-R41-S41 -> 0
G43: INGRESOS POR VENTAS ANUALES
D44: =B7 -> Kit sensórico e integración de campo | G44: TOTAL | H44: Mes 1 | I44: Mes 2 | J44: Mes 3 | K44: Mes 4 | L44: Mes 5 | M44: Mes 6 | N44: Mes 7 | O44: Mes 8 | P44: Mes 9 | Q44: Mes 10 | R44: Mes 11 | S44: Mes 12 | T44: Salir exacto
D45: Nº Productos/Servicios | G45: =F7 -> 5 | H45: 0 | I45: 0 | J45: 0 | K45: 0 | L45: 0 | M45: 0 | N45: 1 | O45: 1 | P45: 1 | Q45: 1 | R45: 1 | S45: 0 | T45: =G45-H45-I45-J45-K45-L45-M45-N45-O45-P45-Q45-R45-S45 -> 0
D46: Precio de venta | G46: =C16 -> 1200 | H46: =G46 -> 1200 | I46: =G46 -> 1200 | J46: =G46 -> 1200 | K46: =G46 -> 1200 | L46: =G46 -> 1200 | M46: =G46 -> 1200 | N46: =G46 -> 1200 | O46: =G46 -> 1200 | P46: =G46 -> 1200 | Q46: =G46 -> 1200 | R46: =G46 -> 1200 | S46: =G46 -> 1200
D47: Ingresos ventas | G47: =G45*G46 -> 6000 | H47: =H45*H46 -> 0 | I47: =I45*I46 -> 0 | J47: =J45*J46 -> 0 | K47: =K45*K46 -> 0 | L47: =L45*L46 -> 0 | M47: =M45*M46 -> 0 | N47: =N45*N46 -> 1200 | ... S47: =S45*S46 -> 0 | T47: =G47-H47-I47-J47-K47-L47-M47-N47-O47-P47-Q47-R47-S47 -> 0
...

Sheet Liquidación de IVA
B3: Liquidación de IVA
B5: 1º TRIMESTRE | H5: TOTALES | I5: €
C6: MES 1 | D6: MES 2 | E6: MES 3 | H6: Total IVA Soportado | I6: =C8+D8+E8+C14+D14+E14+C20+D20+E20+C26+D26+E26 -> 24430.945
B7: Repercutido | C7: =(('Costes produción y ventas'!E13-'Costes produción y ventas'!C13)*'Costes produción y ventas'!H21)+(('Costes produción y ventas'!E14-'Costes produción y ventas'!C14)*'Costes produción y ventas'!H29)+(('Costes produción y ventas'!E15-'Costes produción y ventas'!C15)*'Costes produción y ventas'!H37)+(('Costes produción y ventas'!E16-'Costes produción y ventas'!C16)*'Costes produción y ventas'!H45)+(('Costes produción y ventas'!E17-'Costes produción y ventas'!C17)*'Costes produción y ventas'!H53) -> 0 | D7: =(('Costes produción y ventas'!E13-'Costes produción y ventas'!C13)*'Costes produción y ventas'!I21)+(('Costes produción y ventas'!E14-'Costes produción y ventas'!C14)*'Costes produción y ventas'!I29)+(('Costes produción y ventas'!E15-'Costes produción y ventas'!C15)*'Costes produción y ventas'!I37)+(('Costes produción y ventas'!E16-'Costes produción y ventas'!C16)*'Costes produción y ventas'!I45)+(('Costes produción y ventas'!E17-'Costes produción y ventas'!C17)*'Costes produción y ventas'!I53) -> 0 | E7: =(('Costes produción y ventas'!E13-'Costes produción y ventas'!C13)*'Costes produción y ventas'!J21)+(('Costes produción y ventas'!E14-'Costes produción y ventas'!C14)*'Costes produción y ventas'!J29)+(('Costes produción y ventas'!E15-'Costes produción y ventas'!C15)*'Costes produción y ventas'!J37)+(('Costes produción y ventas'!E16-'Costes produción y ventas'!C16)*'Costes produción y ventas'!J45)+(('Costes produción y ventas'!E17-'Costes produción y ventas'!C17)*'Costes produción y ventas'!J53) -> 105 | H7: Total IVA Repercutido | I7: =C7+D7+E7+C13+D13+E13+C19+D19+E19+C25+D25+E25 -> 8295
B8: Soportado | C8: =(('Costes produción y ventas'!E4-'Costes produción y ventas'!C4)*'Costes produción y ventas'!H21)+(('Costes produción y ventas'!E5-'Costes produción y ventas'!C5)*'Costes produción y ventas'!H29)+(('Costes produción y ventas'!E6-'Costes produción y ventas'!C6)*'Costes produción y ventas'!H37)+(('Costes produción y ventas'!E7-'Costes produción y ventas'!C7)*'Costes produción y ventas'!H45)+(('Costes produción y ventas'!E8-'Costes produción y ventas'!C8)*'Costes produción y ventas'!H53)+('Gasto Fijos y Variables'!F23+'Gasto Fijos y Variables'!F43)+'Inversión Inicial'!K12 -> 19628 | D8: =(('Costes produción y ventas'!E4-'Costes produción y ventas'!C4)*'Costes produción y ventas'!I21)+(('Costes produción y ventas'!E5-'Costes produción y ventas'!C5)*'Costes produción y ventas'!I29)+(('Costes produción y ventas'!E6-'Costes produción y ventas'!C6)*'Costes produción y ventas'!I37)+(('Costes produción y ventas'!E7-'Costes produción y ventas'!C7)*'Costes produción y ventas'!I45)+(('Costes produción y ventas'!E8-'Costes produción y ventas'!C8)*'Costes produción y ventas'!I53)+('Gasto Fijos y Variables'!J23+'Gasto Fijos y Variables'!J43) -> 255.5 | E8: =(('Costes produción y ventas'!E4-'Costes produción y ventas'!C4)*'Costes produción y ventas'!J21)+(('Costes produción y ventas'!E5-'Costes produción y ventas'!C5)*'Costes produción y ventas'!J29)+(('Costes produción y ventas'!E6-'Costes produción y ventas'!C6)*'Costes produción y ventas'!J37)+(('Costes produción y ventas'!E7-'Costes produción y ventas'!C7)*'Costes produción y ventas'!J45)+(('Costes produción y ventas'!E8-'Costes produción y ventas'!C8)*'Costes produción y ventas'!J53)+('Gasto Fijos y Variables'!N23+'Gasto Fijos y Variables'!N43) -> 282.8 | H8: Saldo Primer Trimestre | I8: =C9+D9+E9 -> -20061.3
B9: Devengado | C9: =C7-C8 -> -19628 | D9: =D7-D8 -> -255.5 | E9: =E7-E8 -> -177.8 | H9: Saldo Segundo Trimestre | I9: =C15+D15+E15 -> 172.2
H10: Saldo Tercer Trimestre | I10: =C21+D21+E21 -> 1855.42
B11: 2º TRIMESTRE | H11: Saldo Cuarto Trimestre | I11: =C27+D27+E27 -> 1897.735
C12: MES 4 | D12: MES 5 | E12: MES 6 | H12: HP deudor/acreedor por IVA | I12: =I11 -> 1897.735
B13: Repercutido | C13: =(('Costes produción y ventas'!E13-'Costes produción y ventas'!C13)*'Costes produción y ventas'!K21)+(('Costes produción y ventas'!E14-'Costes produción y ventas'!C14)*'Costes produción y ventas'!K29)+(('Costes produción y ventas'!E15-'Costes produción y ventas'!C15)*'Costes produción y ventas'!K37)+(('Costes produción y ventas'!E16-'Costes produción y ventas'!C16)*'Costes produción y ventas'!K45)+(('Costes produción y ventas'!E17-'Costes produción y ventas'!C17)*'Costes produción y ventas'!K53) -> 262.5 | D13: =(('Costes produción y ventas'!E13-'Costes produción y ventas'!C13)*'Costes produción y ventas'!L21)+(('Costes produción y ventas'!E14-'Costes produción y ventas'!C14)*'Costes produción y ventas'!L29)+(('Costes produción y ventas'!E15-'Costes produción y ventas'!C15)*'Costes produción y ventas'!L37)+(('Costes produción y ventas'!E16-'Costes produción y ventas'!C16)*'Costes produción y ventas'!L45)+(('Costes produción y ventas'!E17-'Costes produción y ventas'!C17)*'Costes produción y ventas'!L53) -> 315 | E13: =(('Costes produción y ventas'!E13-'Costes produción y ventas'!C13)*'Costes produción y ventas'!M21)+(('Costes produción y ventas'!E14-'Costes produción y ventas'!C14)*'Costes produción y ventas'!M29)+(('Costes produción y ventas'!E15-'Costes produción y ventas'!C15)*'Costes produción y ventas'!M37)+(('Costes produción y ventas'!E16-'Costes produción y ventas'!C16)*'Costes produción y ventas'!M45)+(('Costes produción y ventas'!E17-'Costes produción y ventas'!C17)*'Costes produción y ventas'!M53) -> 682.5
B14: Soportado | C14: =(('Costes produción y ventas'!E4-'Costes produción y ventas'!C4)*'Costes produción y ventas'!K21)+(('Costes produción y ventas'!E5-'Costes produción y ventas'!C5)*'Costes produción y ventas'!K29)+(('Costes produción y ventas'!E6-'Costes produción y ventas'!C6)*'Costes produción y ventas'!K37)+(('Costes produción y ventas'!E7-'Costes produción y ventas'!C7)*'Costes produción y ventas'!K45)+(('Costes produción y ventas'!E8-'Costes produción y ventas'!C8)*'Costes produción y ventas'!K53)+('Gasto Fijos y Variables'!R23+'Gasto Fijos y Variables'!R43) -> 327.95 | D14: =(('Costes produción y ventas'!E4-'Costes produción y ventas'!C4)*'Costes produción y ventas'!L21)+(('Costes produción y ventas'!E5-'Costes produción y ventas'!C5)*'Costes produción y ventas'!L29)+(('Costes produción y ventas'!E6-'Costes produción y ventas'!C6)*'Costes produción y ventas'!L37)+(('Costes produción y ventas'!E7-'Costes produción y ventas'!C7)*'Costes produción y ventas'!L45)+(('Costes produción y ventas'!E8-'Costes produción y ventas'!C8)*'Costes produción y ventas'!L53)+('Gasto Fijos y Variables'!V23+'Gasto Fijos y Variables'!V43) -> 341.6 | E14: =(('Costes produción y ventas'!E4-'Costes produción y ventas'!C4)*'Costes produción y ventas'!M21)+(('Costes produción y ventas'!E5-'Costes produción y ventas'!C5)*'Costes produción y ventas'!M29)+(('Costes produción y ventas'!E6-'Costes produción y ventas'!C6)*'Costes produción y ventas'!M37)+(('Costes produción y ventas'!E7-'Costes produción y ventas'!C7)*'Costes produción y ventas'!M45)+(('Costes produción y ventas'!E8-'Costes produción y ventas'!C8)*'Costes produción y ventas'!M53)+('Gasto Fijos y Variables'!Z23+'Gasto Fijos y Variables'!Z43) -> 418.25
B15: Devengado | C15: =C13-C14 -> -65.45 | D15: =D13-D14 -> -26.6 | E15: =E13-E14 -> 264.25
B17: 3º TRIMESTRE
C18: MES 7 | D18: MES 8 | E18: MES 9
B19: Repercutido | C19: =(('Costes produción y ventas'!E13-'Costes produción y ventas'!C13)*'Costes produción y ventas'!N21)+(('Costes produción y ventas'!E14-'Costes produción y ventas'!C14)*'Costes produción y ventas'!N29)+(('Costes produción y ventas'!E15-'Costes produción y ventas'!C15)*'Costes produción y ventas'!N37)+(('Costes produción y ventas'!E16-'Costes produción y ventas'!C16)*'Costes produción y ventas'!N45)+(('Costes produción y ventas'!E17-'Costes produción y ventas'!C17)*'Costes produción y ventas'!N53) -> 987 | D19: =(('Costes produción y ventas'!E13-'Costes produción y ventas'!C13)*'Costes produción y ventas'!O21)+(('Costes produción y ventas'!E14-'Costes produción y ventas'!C14)*'Costes produción y ventas'!O29)+(('Costes produción y ventas'!E15-'Costes produción y ventas'!C15)*'Costes produción y ventas'!O37)+(('Costes produción y ventas'!E16-'Costes produción y ventas'!C16)*'Costes produción y ventas'!O45)+(('Costes produción y ventas'!E17-'Costes produción y ventas'!C17)*'Costes produción y ventas'!O53) -> 1284.5 | E19: =(('Costes produción y ventas'!E13-'Costes produción y ventas'!C13)*'Costes produción y ventas'!P21)+(('Costes produción y ventas'!E14-'Costes produción y ventas'!C14)*'Costes produción y ventas'!P29)+(('Costes produción y ventas'!E15-'Costes produción y ventas'!C15)*'Costes produción y ventas'!P37)+(('Costes produción y ventas'!E16-'Costes produción y ventas'!C16)*'Costes produción y ventas'!P45)+(('Costes produción y ventas'!E17-'Costes produción y ventas'!C17)*'Costes produción y ventas'!P53) -> 1337
B20: Soportado | C20: =(('Costes produción y ventas'!E4-'Costes produción y ventas'!C4)*'Costes produción y ventas'!N21)+(('Costes produción y ventas'!E5-'Costes produción y ventas'!C5)*'Costes produción y ventas'!N29)+(('Costes produción y ventas'!E6-'Costes produción y ventas'!C6)*'Costes produción y ventas'!N37)+(('Costes produción y ventas'!E7-'Costes produción y ventas'!C7)*'Costes produción y ventas'!N45)+(('Costes produción y ventas'!E8-'Costes produción y ventas'!C8)*'Costes produción y ventas'!N53)+('Gasto Fijos y Variables'!AD23+'Gasto Fijos y Variables'!AD43) -> 515.9 | D20: =(('Costes produción y ventas'!E4-'Costes produción y ventas'!C4)*'Costes produción y ventas'!O21)+(('Costes produción y ventas'!E5-'Costes produción y ventas'!C5)*'Costes produción y ventas'!O29)+(('Costes produción y ventas'!E6-'Costes produción y ventas'!C6)*'Costes produción y ventas'!O37)+(('Costes produción y ventas'!E7-'Costes produción y ventas'!C7)*'Costes produción y ventas'!O45)+(('Costes produción y ventas'!E8-'Costes produción y ventas'!C8)*'Costes produción y ventas'!O53)+('Gasto Fijos y Variables'!AH23+'Gasto Fijos y Variables'!AH43) -> 611.765 | E20: =(('Costes produción y ventas'!E4-'Costes produción y ventas'!C4)*'Costes produción y ventas'!P21)+(('Costes produción y ventas'!E5-'Costes produción y ventas'!C5)*'Costes produción y ventas'!P29)+(('Costes produción y ventas'!E6-'Costes produción y ventas'!C6)*'Costes produción y ventas'!P37)+(('Costes produción y ventas'!E7-'Costes produción y ventas'!C7)*'Costes produción y ventas'!P45)+(('Costes produción y ventas'!E8-'Costes produción y ventas'!C8)*'Costes produción y ventas'!P53)+('Gasto Fijos y Variables'!AL23+'Gasto Fijos y Variables'!AL43) -> 625.415
B21: Devengado | C21: =C19-C20 -> 471.1 | D21: =D19-D20 -> 672.735 | E21: =E19-E20 -> 711.585
B23: 4º TRIMESTRE
C24: MES 10 | D24: MES 11 | E24: MES 12
B25: Repercutido | C25: =(('Costes produción y ventas'!E13-'Costes produción y ventas'!C13)*'Costes produción y ventas'!Q21)+(('Costes produción y ventas'!E14-'Costes produción y ventas'!C14)*'Costes produción y ventas'!Q29)+(('Costes produción y ventas'!E15-'Costes produción y ventas'!C15)*'Costes produción y ventas'!Q37)+(('Costes produción y ventas'!E16-'Costes produción y ventas'!C16)*'Costes produción y ventas'!Q45)+(('Costes produción y ventas'!E17-'Costes produción y ventas'!C17)*'Costes produción y ventas'!Q53) -> 1389.5 | D25: =(('Costes produción y ventas'!E13-'Costes produción y ventas'!C13)*'Costes produción y ventas'!R21)+(('Costes produción y ventas'!E14-'Costes produción y ventas'!C14)*'Costes produción y ventas'!R29)+(('Costes produción y ventas'!E15-'Costes produción y ventas'!C15)*'Costes produción y ventas'!R37)+(('Costes produción y ventas'!E16-'Costes produción y ventas'!C16)*'Costes produción y ventas'!R45)+(('Costes produción y ventas'!E17-'Costes produción y ventas'!C17)*'Costes produción y ventas'!R53) -> 1039.5 | E25: =(('Costes produción y ventas'!E13-'Costes produción y ventas'!C13)*'Costes produción y ventas'!S21)+(('Costes produción y ventas'!E14-'Costes produción y ventas'!C14)*'Costes produción y ventas'!S29)+(('Costes produción y ventas'!E15-'Costes produción y ventas'!C15)*'Costes produción y ventas'!S37)+(('Costes produción y ventas'!E16-'Costes produción y ventas'!C16)*'Costes produción y ventas'!S45)+(('Costes produción y ventas'!E17-'Costes produción y ventas'!C17)*'Costes produción y ventas'!S53) -> 892.5
B26: Soportado | C26: =(('Costes produción y ventas'!E4-'Costes produción y ventas'!C4)*'Costes produción y ventas'!Q21)+(('Costes produción y ventas'!E5-'Costes produción y ventas'!C5)*'Costes produción y ventas'!Q29)+(('Costes produción y ventas'!E6-'Costes produción y ventas'!C6)*'Costes produción y ventas'!Q37)+(('Costes produción y ventas'!E7-'Costes produción y ventas'!C7)*'Costes produción y ventas'!Q45)+(('Costes produción y ventas'!E8-'Costes produción y ventas'!C8)*'Costes produción y ventas'!Q53)+('Gasto Fijos y Variables'!AP23+'Gasto Fijos y Variables'!AP43) -> 639.065 | D26: =(('Costes produción y ventas'!E4-'Costes produción y ventas'!C4)*'Costes produción y ventas'!R21)+(('Costes produción y ventas'!E5-'Costes produción y ventas'!C5)*'Costes produción y ventas'!R29)+(('Costes produción y ventas'!E6-'Costes produción y ventas'!C6)*'Costes produción y ventas'!R37)+(('Costes produción y ventas'!E7-'Costes produción y ventas'!C7)*'Costes produción y ventas'!R45)+(('Costes produción y ventas'!E8-'Costes produción y ventas'!C8)*'Costes produción y ventas'!R53)+('Gasto Fijos y Variables'!AT23+'Gasto Fijos y Variables'!AT43) -> 548.45 | E26: =(('Costes produción y ventas'!E4-'Costes produción y ventas'!C4)*'Costes produción y ventas'!S21)+(('Costes produción y ventas'!E5-'Costes produción y ventas'!C5)*'Costes produción y ventas'!S29)+(('Costes produción y ventas'!E6-'Costes produción y ventas'!C6)*'Costes produción y ventas'!S37)+(('Costes produción y ventas'!E7-'Costes produción y ventas'!C7)*'Costes produción y ventas'!S45)+(('Costes produción y ventas'!E8-'Costes produción y ventas'!C8)*'Costes produción y ventas'!S53)+('Gasto Fijos y Variables'!AX23+'Gasto Fijos y Variables'!AX43) -> 236.25
B27: Devengado | C27: =C25-C26 -> 750.435 | D27: =D25-D26 -> 491.05 | E27: =E25-E26 -> 656.25
B29: Esta información se obtiene de manera automática, teniendo en cuenta datos que se han introducido en apartados anteriores.

Sheet Gasto Fijos y Variables
B3: Gastos Fijos y Variables
D5: MES 1 | H5: MES 2 | L5: MES 3 | P5: MES 4 | T5: MES 5 | X5: MES 6 | AB5: MES 7 | AF5: MES 8 | AJ5: MES 9 | AN5: MES 10 | AR5: MES 11 | AV5: MES 12
B6: GASTOS FIJOS | C6: Imp Total S/IVA | D6: imp. Sin IVA | E6: % | F6: imp. IVA | G6: Total | H6: imp. Sin IVA | I6: % | J6: imp. IVA | K6: Total | L6: imp. Sin IVA | M6: % | N6: imp. IVA | O6: Total | P6: imp. Sin IVA | Q6: % | R6: imp. IVA | S6: Total | T6: imp. Sin IVA | U6: % | V6: imp. IVA | W6: Total | X6: imp. Sin IVA | Y6: % | Z6: imp. IVA | AA6: Total | AB6: imp. Sin IVA | AC6: % | AD6: imp. IVA | AE6: Total | AF6: imp. Sin IVA | AG6: % | AH6: imp. IVA | AI6: Total | AJ6: imp. Sin IVA | AK6: % | AL6: imp. IVA | AM6: Total | AN6: imp. Sin IVA | AO6: % | AP6: imp. IVA | AQ6: Total | AR6: imp. Sin IVA | AS6: % | AT6: imp. IVA | AU6: Total | AV6: imp. Sin IVA | AW6: % | AX6: imp. IVA | AY6: Total | AZ6: Salir Exacto
B7: Agua | C7: 0 | D7: 0 | E7: 0.21 | F7: =D7*E7 -> 0 | G7: =D7+F7 -> 0 | H7: 0 | I7: 0.21 | J7: =H7*I7 -> 0 | K7: =H7+J7 -> 0 | L7: 0 | M7: 0.21 | N7: =L7*M7 -> 0 | O7: =L7+N7 -> 0 | P7: 0 | Q7: 0.21 | R7: =P7*Q7 -> 0 | S7: =P7+R7 -> 0 | T7: 0 | U7: 0.21 | V7: =T7*U7 -> 0 | W7: =T7+V7 -> 0 | X7: 0 | Y7: 0.21 | Z7: =X7*Y7 -> 0 | AA7: =X7+Z7 -> 0 | AB7: 0 | AC7: 0.21 | AD7: =AB7*AC7 -> 0 | AE7: =AB7+AD7 -> 0 | AF7: 0 | AG7: 0.21 | AH7: =AF7*AG7 -> 0 | AI7: =AF7+AH7 -> 0 | AJ7: 0 | AK7: 0.21 | AL7: =AJ7*AK7 -> 0 | AM7: =AJ7+AL7 -> 0 | AN7: 0 | AO7: 0.21 | AP7: =AN7*AO7 -> 0 | AQ7: =AN7+AP7 -> 0 | AR7: 0 | AS7: 0.21 | AT7: =AR7*AS7 -> 0 | AU7: =AR7+AT7 -> 0 | AV7: 0 | AW7: 0.21 | AX7: =AV7*AW7 -> 0 | AY7: =AV7+AX7 -> 0 | AZ7: =D7+H7+L7+P7+T7+X7+AB7+AF7+AJ7+AN7+AR7+AV7-C7 -> 0
B8: Luz | C8: 0 | D8: 0 | E8: 0.21 | F8: =D8*E8 -> 0 | G8: =D8+F8 -> 0 | H8: 0 | I8: 0.21 | J8: =H8*I8 -> 0 | K8: =H8+J8 -> 0 | L8: 0 | M8: 0.21 | N8: =L8*M8 -> 0 | O8: =L8+N8 -> 0 | P8: 0 | Q8: 0.21 | R8: =P8*Q8 -> 0 | S8: =P8+R8 -> 0 | T8: 0 | U8: 0.21 | V8: =T8*U8 -> 0 | W8: =T8+V8 -> 0 | X8: 0 | Y8: 0.21 | Z8: =X8*Y8 -> 0 | AA8: =X8+Z8 -> 0 | AB8: 0 | AC8: 0.21 | AD8: =AB8*AC8 -> 0 | AE8: =AB8+AD8 -> 0 | AF8: 0 | AG8: 0.21 | AH8: =AF8*AG8 -> 0 | AI8: =AF8+AH8 -> 0 | AJ8: 0 | AK8: 0.21 | AL8: =AJ8*AK8 -> 0 | AM8: =AJ8+AL8 -> 0 | AN8: 0 | AO8: 0.21 | AP8: =AN8*AO8 -> 0 | AQ8: =AN8+AP8 -> 0 | AR8: 0 | AS8: 0.21 | AT8: =AR8*AS8 -> 0 | AU8: =AR8+AT8 -> 0 | AV8: 0 | AW8: 0.21 | AX8: =AV8*AW8 -> 0 | AY8: =AV8+AX8 -> 0 | AZ8: =D8+H8+L8+P8+T8+X8+AB8+AF8+AJ8+AN8+AR8+AV8-C8 -> 0
B9: Gas | C9: 0 | D9: 0 | E9: 0.21 | F9: =D9*E9 -> 0 | G9: =D9+F9 -> 0 | H9: 0 | I9: 0.21 | J9: =H9*I9 -> 0 | K9: =H9+J9 -> 0 | L9: 0 | M9: 0.21 | N9: =L9*M9 -> 0 | O9: =L9+N9 -> 0 | P9: 0 | Q9: 0.21 | R9: =P9*Q9 -> 0 | S9: =P9+R9 -> 0 | T9: 0 | U9: 0.21 | V9: =T9*U9 -> 0 | W9: =T9+V9 -> 0 | X9: 0 | Y9: 0.21 | Z9: =X9*Y9 -> 0 | AA9: =X9+Z9 -> 0 | AB9: 0 | AC9: 0.21 | AD9: =AB9*AC9 -> 0 | AE9: =AB9+AD9 -> 0 | AF9: 0 | AG9: 0.21 | AH9: =AF9*AG9 -> 0 | AI9: =AF9+AH9 -> 0 | AJ9: 0 | AK9: 0.21 | AL9: =AJ9*AK9 -> 0 | AM9: =AJ9+AL9 -> 0 | AN9: 0 | AO9: 0.21 | AP9: =AN9*AO9 -> 0 | AQ9: =AN9+AP9 -> 0 | AR9: 0 | AS9: 0.21 | AT9: =AR9*AS9 -> 0 | AU9: =AR9+AT9 -> 0 | AV9: 0 | AW9: 0.21 | AX9: =AV9*AW9 -> 0 | AY9: =AV9+AX9 -> 0 | AZ9: =D9+H9+L9+P9+T9+X9+AB9+AF9+AJ9+AN9+AR9+AV9-C9 -> 0
B10: Internet | C10: 1800 | D10: 150 | E10: 0.21 | F10: =D10*E10 -> 31.5 | G10: =D10+F10 -> 181.5 | H10: 150 | I10: 0.21 | J10: =H10*I10 -> 31.5 | K10: =H10+J10 -> 181.5 | L10: 150 | M10: 0.21 | N10: =L10*M10 -> 31.5 | O10: =L10+N10 -> 181.5 | P10: 150 | Q10: 0.21 | R10: =P10*Q10 -> 31.5 | S10: =P10+R10 -> 181.5 | T10: 150 | U10: 0.21 | V10: =T10*U10 -> 31.5 | W10: =T10+V10 -> 181.5 | X10: 150 | Y10: 0.21 | Z10: =X10*Y10 -> 31.5 | AA10: =X10+Z10 -> 181.5 | AB10: 150 | AC10: 0.21 | AD10: =AB10*AC10 -> 31.5 | AE10: =AB10+AD10 -> 181.5 | AF10: 150 | AG10: 0.21 | AH10: =AF10*AG10 -> 31.5 | AI10: =AF10+AH10 -> 181.5 | AJ10: 150 | AK10: 0.21 | AL10: =AJ10*AK10 -> 31.5 | AM10: =AJ10+AL10 -> 181.5 | AN10: 150 | AO10: 0.21 | AP10: =AN10*AO10 -> 31.5 | AQ10: =AN10+AP10 -> 181.5 | AR10: 150 | AS10: 0.21 | AT10: =AR10*AS10 -> 31.5 | AU10: =AR10+AT10 -> 181.5 | AV10: 0 | AW10: 0.21 | AX10: =AV10*AW10 -> 0 | AY10: =AV10+AX10 -> 0 | AZ10: =D10+H10+L10+P10+T10+X10+AB10+AF10+AJ10+AN10+AR10+AV10-C10 -> -150
B11: Telefonia | C11: 0 | D11: 0 | E11: 0.21 | F11: =D11*E11 -> 0 | G11: =D11+F11 -> 0 | H11: 0 | I11: 0.21 | J11: =H11*I11 -> 0 | K11: =H11+J11 -> 0 | L11: 0 | M11: 0.21 | N11: =L11*M11 -> 0 | O11: =L11+N11 -> 0 | P11: 0 | Q11: 0.21 | R11: =P11*Q11 -> 0 | S11: =P11+R11 -> 0 | T11: 0 | U11: 0.21 | V11: =T11*U11 -> 0 | W11: =T11+V11 -> 0 | X11: 0 | Y11: 0.21 | Z11: =X11*Y11 -> 0 | AA11: =X11+Z11 -> 0 | AB11: 0 | AC11: 0.21 | AD11: =AB11*AC11 -> 0 | AE11: =AB11+AD11 -> 0 | AF11: 0 | AG11: 0.21 | AH11: =AF11*AG11 -> 0 | AI11: =AF11+AH11 -> 0 | AJ11: 0 | AK11: 0.21 | AL11: =AJ11*AK11 -> 0 | AM11: =AJ11+AL11 -> 0 | AN11: 0 | AO11: 0.21 | AP11: =AN11*AO11 -> 0 | AQ11: =AN11+AP11 -> 0 | AR11: 0 | AS11: 0.21 | AT11: =AR11*AS11 -> 0 | AU11: =AR11+AT11 -> 0 | AV11: 0 | AW11: 0.21 | AX11: =AV11*AW11 -> 0 | AY11: =AV11+AX11 -> 0 | AZ11: =D11+H11+L11+P11+T11+X11+AB11+AF11+AJ11+AN11+AR11+AV11-C11 -> 0
B12: Alquiler | C12: 3600 | D12: 300 | E12: 0.21 | F12: =D12*E12 -> 63 | G12: =D12+F12 -> 363 | H12: 300 | I12: 0.21 | J12: =H12*I12 -> 63 | K12: =H12+J12 -> 363 | L12: 300 | M12: 0.21 | N12: =L12*M12 -> 63 | O12: =L12+N12 -> 363 | P12: 300 | Q12: 0.21 | R12: =P12*Q12 -> 63 | S12: =P12+R12 -> 363 | T12: 300 | U12: 0.21 | V12: =T12*U12 -> 63 | W12: =T12+V12 -> 363 | X12: 300 | Y12: 0.21 | Z12: =X12*Y12 -> 63 | AA12: =X12+Z12 -> 363 | AB12: 300 | AC12: 0.21 | AD12: =AB12*AC12 -> 63 | AE12: =AB12+AD12 -> 363 | AF12: 300 | AG12: 0.21 | AH12: =AF12*AG12 -> 63 | AI12: =AF12+AH12 -> 363 | AJ12: 300 | AK12: 0.21 | AL12: =AJ12*AK12 -> 63 | AM12: =AJ12+AL12 -> 363 | AN12: 300 | AO12: 0.21 | AP12: =AN12*AO12 -> 63 | AQ12: =AN12+AP12 -> 363 | AR12: 300 | AS12: 0.21 | AT12: =AR12*AS12 -> 63 | AU12: =AR12+AT12 -> 363 | AV12: 0 | AW12: 0.21 | AX12: =AV12*AW12 -> 0 | AY12: =AV12+AX12 -> 0 | AZ12: =D12+H12+L12+P12+T12+X12+AB12+AF12+AJ12+AN12+AR12+AV12-C12 -> -300
B13: Seguros | C13: 1200 | D13: 100 | E13: 0 | G13: =D13 -> 100 | H13: 100 | I13: 0 | K13: =H13 -> 100 | L13: 100 | M13: 0 | O13: =L13 -> 100 | P13: 100 | Q13: 0 | S13: =P13 -> 100 | T13: 100 | U13: 0 | W13: =T13 -> 100 | X13: 100 | Y13: 0 | AA13: =X13 -> 100 | AB13: 100 | AC13: 0 | AE13: =AB13 -> 100 | AF13: 100 | AG13: 0 | AI13: =AF13 -> 100 | AJ13: 100 | AK13: 0 | AM13: =AJ13 -> 100 | AN13: 100 | AO13: 0 | AQ13: =AN13 -> 100 | AR13: 100 | AS13: 0 | AU13: =AR13 -> 100 | AV13: 0 | AW13: 0 | AY13: =AV13 -> 0 | AZ13: =D13+H13+L13+P13+T13+X13+AB13+AF13+AJ13+AN13+AR13+AV13-C13 -> -100
B14: Gastos de gestoria | C14: 2400 | D14: 200 | E14: 0.21 | F14: =D14*E14 -> 42 | G14: =D14+F14 -> 242 | H14: 200 | I14: 0.21 | J14: =H14*I14 -> 42 | K14: =H14+J14 -> 242 | L14: 200 | M14: 0.21 | N14: =L14*M14 -> 42 | O14: =L14+N14 -> 242 | P14: 200 | Q14: 0.21 | R14: =P14*Q14 -> 42 | S14: =P14+R14 -> 242 | T14: 200 | U14: 0.21 | V14: =T14*U14 -> 42 | W14: =T14+V14 -> 242 | X14: 200 | Y14: 0.21 | Z14: =X14*Y14 -> 42 | AA14: =X14+Z14 -> 242 | AB14: 200 | AC14: 0.21 | AD14: =AB14*AC14 -> 42 | AE14: =AB14+AD14 -> 242 | AF14: 200 | AG14: 0.21 | AH14: =AF14*AG14 -> 42 | AI14: =AF14+AH14 -> 242 | AJ14: 200 | AK14: 0.21 | AL14: =AJ14*AK14 -> 42 | AM14: =AJ14+AL14 -> 242 | AN14: 200 | AO14: 0.21 | AP14: =AN14*AO14 -> 42 | AQ14: =AN14+AP14 -> 242 | AR14: 200 | AS14: 0.21 | AT14: =AR14*AS14 -> 42 | AU14: =AR14+AT14 -> 242 | AV14: 0 | AW14: 0.21 | AX14: =AV14*AW14 -> 0 | AY14: =AV14+AX14 -> 0 | AZ14: =D14+H14+L14+P14+T14+X14+AB14+AF14+AJ14+AN14+AR14+AV14-C14 -> -200
B15: Marketing | C15: 4000 | D15: 333.33333 | E15: 0.21 | F15: =D15*E15 -> 70 | G15: =D15+F15 -> 403.33333 | H15: 333.33333 | I15: 0.21 | J15: =H15*I15 -> 70 | K15: =H15+J15 -> 403.33333 | L15: 333.33333 | M15: 0.21 | N15: =L15*M15 -> 70 | O15: =L15+N15 -> 403.33333 | P15: 333.33333 | Q15: 0.21 | R15: =P15*Q15 -> 70 | S15: =P15+R15 -> 403.33333 | T15: 333.33333 | U15: 0.21 | V15: =T15*U15 -> 70 | W15: =T15+V15 -> 403.33333 | X15: 333.33333 | Y15: 0.21 | Z15: =X15*Y15 -> 70 | AA15: =X15+Z15 -> 403.33333 | AB15: 333.33333 | AC15: 0.21 | AD15: =AB15*AC15 -> 70 | AE15: =AB15+AD15 -> 403.33333 | AF15: 333.33333 | AG15: 0.21 | AH15: =AF15*AG15 -> 70 | AI15: =AF15+AH15 -> 403.33333 | AJ15: 333.33333 | AK15: 0.21 | AL15: =AJ15*AK15 -> 70 | AM15: =AJ15+AL15 -> 403.33333 | AN15: 333.33333 | AO15: 0.21 | AP15: =AN15*AO15 -> 70 | AQ15: =AN15+AP15 -> 403.33333 | AR15: 333.33333 | AS15: 0.21 | AT15: =AR15*AS15 -> 70 | AU15: =AR15+AT15 -> 403.33333 | AV15: 0 | AW15: 0.21 | AX15: =AV15*AW15 -> 0 | AY15: =AV15+AX15 -> 0 | AZ15: =D15+H15+L15+P15+T15+X15+AB15+AF15+AJ15+AN15+AR15+AV15-C15 -> -333.33333
B16: Sueldo de autónomo — incluido en Gastos de Personal (no duplicar) | C16: 0 | D16: 0 | E16: 0 | G16: =D16 -> 0 | H16: 0 | I16: 0 | K16: =H16 -> 0 | L16: 0 | M16: 0 | O16: =L16 -> 0 | P16: 0 | Q16: 0 | S16: =P16 -> 0 | T16: 0 | U16: 0 | W16: =T16 -> 0 | X16: 0 | Y16: 0 | AA16: =X16 -> 0 | AB16: 0 | AC16: 0 | AE16: =AB16 -> 0 | AF16: 0 | AG16: 0 | AI16: =AF16 -> 0 | AJ16: 0 | AK16: 0 | AM16: =AJ16 -> 0 | AN16: 0 | AO16: 0 | AQ16: =AN16 -> 0 | AR16: 0 | AS16: 0 | AU16: =AR16 -> 0 | AV16: 0 | AW16: 0 | AY16: =AV16 -> 0 | AZ16: =D16+H16+L16+P16+T16+X16+AB16+AF16+AJ16+AN16+AR16+AV16-C16 -> 0
B17: RETA — incluido en Gastos de Personal (4.800 €/año; no duplicar) | C17: 0 | D17: 0 | E17: 0 | G17: =D17 -> 0 | H17: 0 | I17: 0 | K17: =H17 -> 0 | L17: 0 | M17: 0 | O17: =L17 -> 0 | P17: 0 | Q17: 0 | S17: =P17 -> 0 | T17: 0 | U17: 0 | W17: =T17 -> 0 | X17: 0 | Y17: 0 | AA17: =X17 -> 0 | AB17: 0 | AC17: 0 | AE17: =AB17 -> 0 | AF17: 0 | AG17: 0 | AI17: =AF17 -> 0 | AJ17: 0 | AK17: 0 | AM17: =AJ17 -> 0 | AN17: 0 | AO17: 0 | AQ17: =AN17 -> 0 | AR17: 0 | AS17: 0 | AU17: =AR17 -> 0 | AV17: 0 | AW17: 0 | AY17: =AV17 -> 0 | AZ17: =D17+H17+L17+P17+T17+X17+AB17+AF17+AJ17+AN17+AR17+AV17-C17 -> 0
B18: … | C18: 0 | D18: 0 | E18: 0.21 | F18: =D18*E18 -> 0 | G18: =D18+F18 -> 0 | H18: 0 | I18: 0.21 | J18: =H18*I18 -> 0 | K18: =H18+J18 -> 0 | L18: 0 | M18: 0.21 | N18: =L18*M18 -> 0 | O18: =L18+N18 -> 0 | P18: 0 | Q18: 0.21 | R18: =P18*Q18 -> 0 | S18: =P18+R18 -> 0 | T18: 0 | U18: 0.21 | V18: =T18*U18 -> 0 | W18: =T18+V18 -> 0 | X18: 0 | Y18: 0.21 | Z18: =X18*Y18 -> 0 | AA18: =X18+Z18 -> 0 | AB18: 0 | AC18: 0.21 | AD18: =AB18*AC18 -> 0 | AE18: =AB18+AD18 -> 0 | AF18: 0 | AG18: 0.21 | AH18: =AF18*AG18 -> 0 | AI18: =AF18+AH18 -> 0 | AJ18: 0 | AK18: 0.21 | AL18: =AJ18*AK18 -> 0 | AM18: =AJ18+AL18 -> 0 | AN18: 0 | AO18: 0.21 | AP18: =AN18*AO18 -> 0 | AQ18: =AN18+AP18 -> 0 | AR18: 0 | AS18: 0.21 | AT18: =AR18*AS18 -> 0 | AU18: =AR18+AT18 -> 0 | AV18: 0 | AW18: 0.21 | AX18: =AV18*AW18 -> 0 | AY18: =AV18+AX18 -> 0 | AZ18: =D18+H18+L18+P18+T18+X18+AB18+AF18+AJ18+AN18+AR18+AV18-C18 -> 0
B19: … | C19: 0 | D19: 0 | E19: 0.21 | F19: =D19*E19 -> 0 | G19: =D19+F19 -> 0 | H19: 0 | I19: 0.21 | J19: =H19*I19 -> 0 | K19: =H19+J19 -> 0 | L19: 0 | M19: 0.21 | N19: =L19*M19 -> 0 | O19: =L19+N19 -> 0 | P19: 0 | Q19: 0.21 | R19: =P19*Q19 -> 0 | S19: =P19+R19 -> 0 | T19: 0 | U19: 0.21 | V19: =T19*U19 -> 0 | W19: =T19+V19 -> 0 | X19: 0 | Y19: 0.21 | Z19: =X19*Y19 -> 0 | AA19: =X19+Z19 -> 0 | AB19: 0 | AC19: 0.21 | AD19: =AB19*AC19 -> 0 | AE19: =AB19+AD19 -> 0 | AF19: 0 | AG19: 0.21 | AH19: =AF19*AG19 -> 0 | AI19: =AF19+AH19 -> 0 | AJ19: 0 | AK19: 0.21 | AL19: =AJ19*AK19 -> 0 | AM19: =AJ19+AL19 -> 0 | AN19: 0 | AO19: 0.21 | AP19: =AN19*AO19 -> 0 | AQ19: =AN19+AP19 -> 0 | AR19: 0 | AS19: 0.21 | AT19: =AR19*AS19 -> 0 | AU19: =AR19+AT19 -> 0 | AV19: 0 | AW19: 0.21 | AX19: =AV19*AW19 -> 0 | AY19: =AV19+AX19 -> 0 | AZ19: =D19+H19+L19+P19+T19+X19+AB19+AF19+AJ19+AN19+AR19+AV19-C19 -> 0
B20: … | C20: 0 | D20: 0 | E20: 0.21 | F20: =D20*E20 -> 0 | G20: =D20+F20 -> 0 | H20: 0 | I20: 0.21 | J20: =H20*I20 -> 0 | K20: =H20+J20 -> 0 | L20: 0 | M20: 0.21 | N20: =L20*M20 -> 0 | O20: =L20+N20 -> 0 | P20: 0 | Q20: 0.21 | R20: =P20*Q20 -> 0 | S20: =P20+R20 -> 0 | T20: 0 | U20: 0.21 | V20: =T20*U20 -> 0 | W20: =T20+V20 -> 0 | X20: 0 | Y20: 0.21 | Z20: =X20*Y20 -> 0 | AA20: =X20+Z20 -> 0 | AB20: 0 | AC20: 0.21 | AD20: =AB20*AC20 -> 0 | AE20: =AB20+AD20 -> 0 | AF20: 0 | AG20: 0.21 | AH20: =AF20*AG20 -> 0 | AI20: =AF20+AH20 -> 0 | AJ20: 0 | AK20: 0.21 | AL20: =AJ20*AK20 -> 0 | AM20: =AJ20+AL20 -> 0 | AN20: 0 | AO20: 0.21 | AP20: =AN20*AO20 -> 0 | AQ20: =AN20+AP20 -> 0 | AR20: 0 | AS20: 0.21 | AT20: =AR20*AS20 -> 0 | AU20: =AR20+AT20 -> 0 | AV20: 0 | AW20: 0.21 | AX20: =AV20*AW20 -> 0 | AY20: =AV20+AX20 -> 0 | AZ20: =D20+H20+L20+P20+T20+X20+AB20+AF20+AJ20+AN20+AR20+AV20-C20 -> 0
B21: … | C21: 0 | D21: 0 | E21: 0.21 | F21: =D21*E21 -> 0 | G21: =D21+F21 -> 0 | H21: 0 | I21: 0.21 | J21: =H21*I21 -> 0 | K21: =H21+J21 -> 0 | L21: 0 | M21: 0.21 | N21: =L21*M21 -> 0 | O21: =L21+N21 -> 0 | P21: 0 | Q21: 0.21 | R21: =P21*Q21 -> 0 | S21: =P21+R21 -> 0 | T21: 0 | U21: 0.21 | V21: =T21*U21 -> 0 | W21: =T21+V21 -> 0 | X21: 0 | Y21: 0.21 | Z21: =X21*Y21 -> 0 | AA21: =X21+Z21 -> 0 | AB21: 0 | AC21: 0.21 | AD21: =AB21*AC21 -> 0 | AE21: =AB21+AD21 -> 0 | AF21: 0 | AG21: 0.21 | AH21: =AF21*AG21 -> 0 | AI21: =AF21+AH21 -> 0 | AJ21: 0 | AK21: 0.21 | AL21: =AJ21*AK21 -> 0 | AM21: =AJ21+AL21 -> 0 | AN21: 0 | AO21: 0.21 | AP21: =AN21*AO21 -> 0 | AQ21: =AN21+AP21 -> 0 | AR21: 0 | AS21: 0.21 | AT21: =AR21*AS21 -> 0 | AU21: =AR21+AT21 -> 0 | AV21: 0 | AW21: 0.21 | AX21: =AV21*AW21 -> 0 | AY21: =AV21+AX21 -> 0 | AZ21: =D21+H21+L21+P21+T21+X21+AB21+AF21+AJ21+AN21+AR21+AV21-C21 -> 0
B22: … | C22: 0 | D22: 0 | E22: 0.21 | F22: =D22*E22 -> 0 | G22: =D22+F22 -> 0 | H22: 0 | I22: 0.21 | J22: =H22*I22 -> 0 | K22: =H22+J22 -> 0 | L22: 0 | M22: 0.21 | N22: =L22*M22 -> 0 | O22: =L22+N22 -> 0 | P22: 0 | Q22: 0.21 | R22: =P22*Q22 -> 0 | S22: =P22+R22 -> 0 | T22: 0 | U22: 0.21 | V22: =T22*U22 -> 0 | W22: =T22+V22 -> 0 | X22: 0 | Y22: 0.21 | Z22: =X22*Y22 -> 0 | AA22: =X22+Z22 -> 0 | AB22: 0 | AC22: 0.21 | AD22: =AB22*AC22 -> 0 | AE22: =AB22+AD22 -> 0 | AF22: 0 | AG22: 0.21 | AH22: =AF22*AG22 -> 0 | AI22: =AF22+AH22 -> 0 | AJ22: 0 | AK22: 0.21 | AL22: =AJ22*AK22 -> 0 | AM22: =AJ22+AL22 -> 0 | AN22: 0 | AO22: 0.21 | AP22: =AN22*AO22 -> 0 | AQ22: =AN22+AP22 -> 0 | AR22: 0 | AS22: 0.21 | AT22: =AR22*AS22 -> 0 | AU22: =AR22+AT22 -> 0 | AV22: 0 | AW22: 0.21 | AX22: =AV22*AW22 -> 0 | AY22: =AV22+AX22 -> 0 | AZ22: =D22+H22+L22+P22+T22+X22+AB22+AF22+AJ22+AN22+AR22+AV22-C22 -> 0
B23: TOTAL DE GASTOS FIJOS | C23: =SUM(C7:C22) -> 13000 | D23: =SUM(D7:D22) -> 1083.3333 | F23: =SUM(F7:F22) -> 206.5 | G23: =SUM(G7:G22) -> 1289.8333 | H23: =SUM(H7:H22) -> 1083.3333 | J23: =SUM(J7:J22) -> 206.5 | K23: =SUM(K7:K22) -> 1289.8333 | L23: =SUM(L7:L22) -> 1083.3333 | N23: =SUM(N7:N22) -> 206.5 | O23: =SUM(O7:O22) -> 1289.8333 | P23: =SUM(P7:P22) -> 1083.3333 | R23: =SUM(R7:R22) -> 206.5 | S23: =SUM(S7:S22) -> 1289.8333 | T23: =SUM(T7:T22) -> 1083.3333 | V23: =SUM(V7:V22) -> 206.5 | W23: =SUM(W7:W22) -> 1289.8333 | X23: =SUM(X7:X22) -> 1083.3333 | Z23: =SUM(Z7:Z22) -> 206.5 | AA23: =SUM(AA7:AA22) -> 1289.8333 | AB23: =SUM(AB7:AB22) -> 1083.3333 | AD23: =SUM(AD7:AD22) -> 206.5 | AE23: =SUM(AE7:AE22) -> 1289.8333 | AF23: =SUM(AF7:AF22) -> 1083.3333 | AH23: =SUM(AH7:AH22) -> 206.5 | AI23: =SUM(AI7:AI22) -> 1289.8333 | AJ23: =SUM(AJ7:AJ22) -> 1083.3333 | AL23: =SUM(AL7:AL22) -> 206.5 | AM23: =SUM(AM7:AM22) -> 1289.8333 | AN23: =SUM(AN7:AN22) -> 1083.3333 | AP23: =SUM(AP7:AP22) -> 206.5 | AQ23: =SUM(AQ7:AQ22) -> 1289.8333 | AR23: =SUM(AR7:AR22) -> 1083.3333 | AT23: =SUM(AT7:AT22) -> 206.5 | AU23: =SUM(AU7:AU22) -> 1289.8333 | AV23: =SUM(AV7:AV22) -> 0 | AX23: =SUM(AX7:AX22) -> 0 | AY23: =SUM(AY7:AY22) -> 0
D26: MES 1 | H26: MES 2 | L26: MES 3 | P26: MES 4 | T26: MES 5 | X26: MES 6 | AB26: MES 7 | AF26: MES 8 | AJ26: MES 9 | AN26: MES 10 | AR26: MES 11 | AV26: MES 12
B27: GASTOS VARIABLES | C27: Imp Total S/IVA | D27: imp. Sin IVA | E27: % | F27: imp. IVA | G27: Total | H27: imp. Sin IVA | I27: % | J27: imp. IVA | K27: Total | L27: imp. Sin IVA | M27: % | N27: imp. IVA | O27: Total | P27: imp. Sin IVA | Q27: % | R27: imp. IVA | S27: Total | T27: imp. Sin IVA | U27: % | V27: imp. IVA | W27: Total | X27: imp. Sin IVA | Y27: % | Z27: imp. IVA | AA27: Total | AB27: imp. Sin IVA | AC27: % | AD27: imp. IVA | AE27: Total | AF27: imp. Sin IVA | AG27: % | AH27: imp. IVA | AI27: Total | AJ27: imp. Sin IVA | AK27: % | AL27: imp. IVA | AM27: Total | AN27: imp. Sin IVA | AO27: % | AP27: imp. IVA | AQ27: Total | AR27: imp. Sin IVA | AS27: % | AT27: imp. IVA | AU27: Total | AV27: imp. Sin IVA | AW27: % | AX27: imp. IVA | AY27: Total | AZ27: Salir Exacto
B28: Combustible | C28: 0 | D28: 0 | E28: 0.21 | F28: =D28*E28 -> 0 | G28: =D28+F28 -> 0 | H28: 0 | I28: 0.21 | J28: =H28*I28 -> 0 | K28: =H28+J28 -> 0 | L28: 0 | M28: 0.21 | N28: =L28*M28 -> 0 | O28: =L28+N28 -> 0 | P28: 0 | Q28: 0.21 | R28: =P28*Q28 -> 0 | S28: =P28+R28 -> 0 | T28: 0 | U28: 0.21 | V28: =T28*U28 -> 0 | W28: =T28+V28 -> 0 | X28: 0 | Y28: 0.21 | Z28: =X28*Y28 -> 0 | AA28: =X28+Z28 -> 0 | AB28: 0 | AC28: 0.21 | AD28: =AB28*AC28 -> 0 | AE28: =AB28+AD28 -> 0 | AF28: 0 | AG28: 0.21 | AH28: =AF28*AG28 -> 0 | AI28: =AF28+AH28 -> 0 | AJ28: 0 | AK28: 0.21 | AL28: =AJ28*AK28 -> 0 | AM28: =AJ28+AL28 -> 0 | AN28: 0 | AO28: 0.21 | AP28: =AN28*AO28 -> 0 | AQ28: =AN28+AP28 -> 0 | AR28: 0 | AS28: 0.21 | AT28: =AR28*AS28 -> 0 | AU28: =AR28+AT28 -> 0 | AV28: 0 | AW28: 0.21 | AX28: =AV28*AW28 -> 0 | AY28: =AV28+AX28 -> 0 | AZ28: =D28+H28+L28+P28+T28+X28+AB28+AF28+AJ28+AN28+AR28+AV28-C28 -> 0
B29: Materias Primas | C29: 0 | D29: 0 | E29: 0.21 | F29: =D29*E29 -> 0 | G29: =D29+F29 -> 0 | H29: 0 | I29: 0.21 | J29: =H29*I29 -> 0 | K29: =H29+J29 -> 0 | L29: 0 | M29: 0.21 | N29: =L29*M29 -> 0 | O29: =L29+N29 -> 0 | P29: 0 | Q29: 0.21 | R29: =P29*Q29 -> 0 | S29: =P29+R29 -> 0 | T29: 0 | U29: 0.21 | V29: =T29*U29 -> 0 | W29: =T29+V29 -> 0 | X29: 0 | Y29: 0.21 | Z29: =X29*Y29 -> 0 | AA29: =X29+Z29 -> 0 | AB29: 0 | AC29: 0.21 | AD29: =AB29*AC29 -> 0 | AE29: =AB29+AD29 -> 0 | AF29: 0 | AG29: 0.21 | AH29: =AF29*AG29 -> 0 | AI29: =AF29+AH29 -> 0 | AJ29: 0 | AK29: 0.21 | AL29: =AJ29*AK29 -> 0 | AM29: =AJ29+AL29 -> 0 | AN29: 0 | AO29: 0.21 | AP29: =AN29*AO29 -> 0 | AQ29: =AN29+AP29 -> 0 | AR29: 0 | AS29: 0.21 | AT29: =AR29*AS29 -> 0 | AU29: =AR29+AT29 -> 0 | AV29: 0 | AW29: 0.21 | AX29: =AV29*AW29 -> 0 | AY29: =AV29+AX29 -> 0 | AZ29: =D29+H29+L29+P29+T29+X29+AB29+AF29+AJ29+AN29+AR29+AV29-C29 -> 0
